{'name': 'root', 'msg': '\u041d\u0435\u0432\u0435\u0440\u043d\u044b\u0439 \u0442\u0438\u043f \u0434\u0430\u043d\u043d\u044b\u0445 \u0434\u043b\u044f \u043e\u0431\u044a\u0435\u043a\u0442\u0430 Runner', 'args': (), 'levelname': 'WARNING', 'levelno': 30, 'pathname': 'C:\\Users\\Daniil\\Documents\\PROGS\\pichon\\HomeWorks\\myDirectory\\module12tests\\module12_4.py', 'filename': 'module12_4.py', 'module': 'module12_4', 'exc_info': (<class 'TypeError'>, TypeError('\u0418\u043c\u044f \u043c\u043e\u0436\u0435\u0442 \u0431\u044b\u0442\u044c \u0442\u043e\u043b\u044c\u043a\u043e \u0441\u0442\u0440\u043e\u043a\u043e\u0439, \u043f\u0435\u0440\u0435\u0434\u0430\u043d\u043e int'), <traceback object at 0x000001B1DC7A4280>), 'exc_text': None, 'stack_info': None, 'lineno': 80, 'funcName': 'test_run', 'created': 1732983223.5915396, 'msecs': 591.0, 'relativeCreated': 3.003358840942383, 'thread': 6364, 'threadName': 'MainThread', 'processName': 'MainProcess', 'process': 12636, 'taskName': None, 'message': '\u041d\u0435\u0432\u0435\u0440\u043d\u044b\u0439 \u0442\u0438\u043f \u0434\u0430\u043d\u043d\u044b\u0445 \u0434\u043b\u044f \u043e\u0431\u044a\u0435\u043a\u0442\u0430 Runner'}sc_time)s| (WARNING | Неверный тип данных для объекта Runner
Traceback (most recent call last):
  File "C:\Users\Daniil\Documents\PROGS\pichon\HomeWorks\myDirectory\module12tests\module12_4.py", line 74, in test_run
    runner1 = Runner(5)
              ^^^^^^^^^
  File "C:\Users\Daniil\Documents\PROGS\pichon\HomeWorks\myDirectory\module12tests\module12_4.py", line 10, in __init__
    raise TypeError(f'Имя может быть только строкой, передано {type(name).__name__}')
TypeError: Имя может быть только строкой, передано int
{'name': 'root', 'msg': '\u041d\u0435\u0432\u0435\u0440\u043d\u0430\u044f \u0441\u043a\u043e\u0440\u043e\u0441\u0442\u044c \u0434\u043b\u044f Runner', 'args': (), 'levelname': 'WARNING', 'levelno': 30, 'pathname': 'C:\\Users\\Daniil\\Documents\\PROGS\\pichon\\HomeWorks\\myDirectory\\module12tests\\module12_4.py', 'filename': 'module12_4.py', 'module': 'module12_4', 'exc_info': (<class 'ValueError'>, ValueError('\u0421\u043a\u043e\u0440\u043e\u0441\u0442\u044c \u043d\u0435 \u043c\u043e\u0436\u0435\u0442 \u0431\u044b\u0442\u044c \u043e\u0442\u0440\u0438\u0446\u0430\u0442\u0435\u043b\u044c\u043d\u043e\u0439, \u0441\u0435\u0439\u0447\u0430\u0441 -10'), <traceback object at 0x000001B1DC7A4580>), 'exc_text': None, 'stack_info': None, 'lineno': 69, 'funcName': 'test_walk', 'created': 1732983223.5935407, 'msecs': 593.0, 'relativeCreated': 5.004405975341797, 'thread': 6364, 'threadName': 'MainThread', 'processName': 'MainProcess', 'process': 12636, 'taskName': None, 'message': '\u041d\u0435\u0432\u0435\u0440\u043d\u0430\u044f \u0441\u043a\u043e\u0440\u043e\u0441\u0442\u044c \u0434\u043b\u044f Runner'}sc_time)s| (WARNING | Неверная скорость для Runner
Traceback (most recent call last):
  File "C:\Users\Daniil\Documents\PROGS\pichon\HomeWorks\myDirectory\module12tests\module12_4.py", line 63, in test_walk
    runner = Runner('TestWalk', -10)
             ^^^^^^^^^^^^^^^^^^^^^^^
  File "C:\Users\Daniil\Documents\PROGS\pichon\HomeWorks\myDirectory\module12tests\module12_4.py", line 15, in __init__
    raise ValueError(f'Скорость не может быть отрицательной, сейчас {speed}')
ValueError: Скорость не может быть отрицательной, сейчас -10
